Internal Server Error: /upload/
Traceback (most recent call last):
  File "C:\Users\kyawz\AppData\Roaming\Python\Python312\site-packages\django\db\backends\utils.py", line 105, in _execute
    return self.cursor.execute(sql, params)
           ^^^^^^^^^^^^^^^^^^^^^^^^^^^^^^^^
  File "C:\Users\kyawz\AppData\Roaming\Python\Python312\site-packages\django\db\backends\mysql\base.py", line 76, in execute
    return self.cursor.execute(query, args)
           ^^^^^^^^^^^^^^^^^^^^^^^^^^^^^^^^
  File "C:\Users\kyawz\AppData\Roaming\Python\Python312\site-packages\MySQLdb\cursors.py", line 179, in execute
    res = self._query(mogrified_query)
          ^^^^^^^^^^^^^^^^^^^^^^^^^^^^
  File "C:\Users\kyawz\AppData\Roaming\Python\Python312\site-packages\MySQLdb\cursors.py", line 330, in _query
    db.query(q)
  File "C:\Users\kyawz\AppData\Roaming\Python\Python312\site-packages\MySQLdb\connections.py", line 261, in query
    _mysql.connection.query(self, query)
MySQLdb.IntegrityError: (1364, "Field 'avg_coverage' doesn't have a default value")

The above exception was the direct cause of the following exception:

Traceback (most recent call last):
  File "C:\Users\kyawz\AppData\Roaming\Python\Python312\site-packages\django\core\handlers\exception.py", line 55, in inner
    response = get_response(request)
               ^^^^^^^^^^^^^^^^^^^^^
  File "C:\Users\kyawz\AppData\Roaming\Python\Python312\site-packages\django\core\handlers\base.py", line 197, in _get_response
    response = wrapped_callback(request, *callback_args, **callback_kwargs)
               ^^^^^^^^^^^^^^^^^^^^^^^^^^^^^^^^^^^^^^^^^^^^^^^^^^^^^^^^^^^^
  File "C:\Users\kyawz\AppData\Roaming\Python\Python312\site-packages\django\contrib\auth\decorators.py", line 23, in _wrapper_view
    return view_func(request, *args, **kwargs)
           ^^^^^^^^^^^^^^^^^^^^^^^^^^^^^^^^^^^
  File "C:\Users\kyawz\AppData\Roaming\Python\Python312\site-packages\django\utils\decorators.py", line 188, in _view_wrapper
    result = _process_exception(request, e)
             ^^^^^^^^^^^^^^^^^^^^^^^^^^^^^^
  File "C:\Users\kyawz\AppData\Roaming\Python\Python312\site-packages\django\utils\decorators.py", line 186, in _view_wrapper
    response = view_func(request, *args, **kwargs)
               ^^^^^^^^^^^^^^^^^^^^^^^^^^^^^^^^^^^
  File "C:\Users\kyawz\Desktop\filecompare_project\filecompare\views.py", line 40, in upload_files
    results = compare_files(file_paths, request.user.id, name_of_comparison)
              ^^^^^^^^^^^^^^^^^^^^^^^^^^^^^^^^^^^^^^^^^^^^^^^^^^^^^^^^^^^^^^
  File "C:\Users\kyawz\Desktop\filecompare_project\filecompare\utils.py", line 485, in compare_files
    comparison = Comparison.objects.create(
                 ^^^^^^^^^^^^^^^^^^^^^^^^^^
  File "C:\Users\kyawz\AppData\Roaming\Python\Python312\site-packages\django\db\models\manager.py", line 87, in manager_method
    return getattr(self.get_queryset(), name)(*args, **kwargs)
           ^^^^^^^^^^^^^^^^^^^^^^^^^^^^^^^^^^^^^^^^^^^^^^^^^^^
  File "C:\Users\kyawz\AppData\Roaming\Python\Python312\site-packages\django\db\models\query.py", line 679, in create
    obj.save(force_insert=True, using=self.db)
  File "C:\Users\kyawz\Desktop\filecompare_project\filecompare\models.py", line 130, in save
    super().save(*args, **kwargs)
  File "C:\Users\kyawz\AppData\Roaming\Python\Python312\site-packages\django\db\models\base.py", line 822, in save
    self.save_base(
  File "C:\Users\kyawz\AppData\Roaming\Python\Python312\site-packages\django\db\models\base.py", line 909, in save_base
    updated = self._save_table(
              ^^^^^^^^^^^^^^^^^
  File "C:\Users\kyawz\AppData\Roaming\Python\Python312\site-packages\django\db\models\base.py", line 1071, in _save_table
    results = self._do_insert(
              ^^^^^^^^^^^^^^^^
  File "C:\Users\kyawz\AppData\Roaming\Python\Python312\site-packages\django\db\models\base.py", line 1112, in _do_insert
    return manager._insert(
           ^^^^^^^^^^^^^^^^
  File "C:\Users\kyawz\AppData\Roaming\Python\Python312\site-packages\django\db\models\manager.py", line 87, in manager_method
    return getattr(self.get_queryset(), name)(*args, **kwargs)
           ^^^^^^^^^^^^^^^^^^^^^^^^^^^^^^^^^^^^^^^^^^^^^^^^^^^
  File "C:\Users\kyawz\AppData\Roaming\Python\Python312\site-packages\django\db\models\query.py", line 1847, in _insert
    return query.get_compiler(using=using).execute_sql(returning_fields)
           ^^^^^^^^^^^^^^^^^^^^^^^^^^^^^^^^^^^^^^^^^^^^^^^^^^^^^^^^^^^^^
  File "C:\Users\kyawz\AppData\Roaming\Python\Python312\site-packages\django\db\models\sql\compiler.py", line 1823, in execute_sql
    cursor.execute(sql, params)
  File "C:\Users\kyawz\AppData\Roaming\Python\Python312\site-packages\django\db\backends\utils.py", line 122, in execute
    return super().execute(sql, params)
           ^^^^^^^^^^^^^^^^^^^^^^^^^^^^
  File "C:\Users\kyawz\AppData\Roaming\Python\Python312\site-packages\django\db\backends\utils.py", line 79, in execute
    return self._execute_with_wrappers(
           ^^^^^^^^^^^^^^^^^^^^^^^^^^^^
  File "C:\Users\kyawz\AppData\Roaming\Python\Python312\site-packages\django\db\backends\utils.py", line 92, in _execute_with_wrappers
    return executor(sql, params, many, context)
           ^^^^^^^^^^^^^^^^^^^^^^^^^^^^^^^^^^^^
  File "C:\Users\kyawz\AppData\Roaming\Python\Python312\site-packages\django\db\backends\utils.py", line 100, in _execute
    with self.db.wrap_database_errors:
  File "C:\Users\kyawz\AppData\Roaming\Python\Python312\site-packages\django\db\utils.py", line 91, in __exit__
    raise dj_exc_value.with_traceback(traceback) from exc_value
  File "C:\Users\kyawz\AppData\Roaming\Python\Python312\site-packages\django\db\backends\utils.py", line 105, in _execute
    return self.cursor.execute(sql, params)
           ^^^^^^^^^^^^^^^^^^^^^^^^^^^^^^^^
  File "C:\Users\kyawz\AppData\Roaming\Python\Python312\site-packages\django\db\backends\mysql\base.py", line 76, in execute
    return self.cursor.execute(query, args)
           ^^^^^^^^^^^^^^^^^^^^^^^^^^^^^^^^
  File "C:\Users\kyawz\AppData\Roaming\Python\Python312\site-packages\MySQLdb\cursors.py", line 179, in execute
    res = self._query(mogrified_query)
          ^^^^^^^^^^^^^^^^^^^^^^^^^^^^
  File "C:\Users\kyawz\AppData\Roaming\Python\Python312\site-packages\MySQLdb\cursors.py", line 330, in _query
    db.query(q)
  File "C:\Users\kyawz\AppData\Roaming\Python\Python312\site-packages\MySQLdb\connections.py", line 261, in query
    _mysql.connection.query(self, query)
django.db.utils.IntegrityError: (1364, "Field 'avg_coverage' doesn't have a default value")
"POST /upload/ HTTP/1.1" 500 479510
Internal Server Error: /upload/
Traceback (most recent call last):
  File "C:\Users\kyawz\AppData\Roaming\Python\Python312\site-packages\django\core\handlers\exception.py", line 55, in inner
    response = get_response(request)
               ^^^^^^^^^^^^^^^^^^^^^
  File "C:\Users\kyawz\AppData\Roaming\Python\Python312\site-packages\django\core\handlers\base.py", line 197, in _get_response
    response = wrapped_callback(request, *callback_args, **callback_kwargs)
               ^^^^^^^^^^^^^^^^^^^^^^^^^^^^^^^^^^^^^^^^^^^^^^^^^^^^^^^^^^^^
  File "C:\Users\kyawz\AppData\Roaming\Python\Python312\site-packages\django\contrib\auth\decorators.py", line 23, in _wrapper_view
    return view_func(request, *args, **kwargs)
           ^^^^^^^^^^^^^^^^^^^^^^^^^^^^^^^^^^^
  File "C:\Users\kyawz\AppData\Roaming\Python\Python312\site-packages\django\utils\decorators.py", line 188, in _view_wrapper
    result = _process_exception(request, e)
             ^^^^^^^^^^^^^^^^^^^^^^^^^^^^^^
  File "C:\Users\kyawz\AppData\Roaming\Python\Python312\site-packages\django\utils\decorators.py", line 186, in _view_wrapper
    response = view_func(request, *args, **kwargs)
               ^^^^^^^^^^^^^^^^^^^^^^^^^^^^^^^^^^^
  File "C:\Users\kyawz\Desktop\filecompare_project\filecompare\views.py", line 40, in upload_files
    results = compare_files(file_paths, request.user.id, name_of_comparison)
              ^^^^^^^^^^^^^^^^^^^^^^^^^^^^^^^^^^^^^^^^^^^^^^^^^^^^^^^^^^^^^^
  File "C:\Users\kyawz\Desktop\filecompare_project\filecompare\utils.py", line 425, in compare_files
    semantic_matches = find_semantic_matches(sentences1, sentences2, threshold=semantic_threshold)
                       ^^^^^^^^^^^^^^^^^^^^^^^^^^^^^^^^^^^^^^^^^^^^^^^^^^^^^^^^^^^^^^^^^^^^^^^^^^^
  File "C:\Users\kyawz\Desktop\filecompare_project\filecompare\utils.py", line 280, in find_semantic_matches
    embeddings1 = model.encode(sentences1)
                  ^^^^^^^^^^^^^^^^^^^^^^^^
  File "C:\Users\kyawz\AppData\Roaming\Python\Python312\site-packages\sentence_transformers\SentenceTransformer.py", line 565, in encode
    if all_embeddings[0].dtype == torch.bfloat16:
       ~~~~~~~~~~~~~~^^^
IndexError: list index out of range
"POST /upload/ HTTP/1.1" 500 106173
Internal Server Error: /upload/
Traceback (most recent call last):
  File "C:\Users\kyawz\AppData\Roaming\Python\Python312\site-packages\django\db\backends\utils.py", line 105, in _execute
    return self.cursor.execute(sql, params)
           ^^^^^^^^^^^^^^^^^^^^^^^^^^^^^^^^
  File "C:\Users\kyawz\AppData\Roaming\Python\Python312\site-packages\django\db\backends\mysql\base.py", line 76, in execute
    return self.cursor.execute(query, args)
           ^^^^^^^^^^^^^^^^^^^^^^^^^^^^^^^^
  File "C:\Users\kyawz\AppData\Roaming\Python\Python312\site-packages\MySQLdb\cursors.py", line 179, in execute
    res = self._query(mogrified_query)
          ^^^^^^^^^^^^^^^^^^^^^^^^^^^^
  File "C:\Users\kyawz\AppData\Roaming\Python\Python312\site-packages\MySQLdb\cursors.py", line 330, in _query
    db.query(q)
  File "C:\Users\kyawz\AppData\Roaming\Python\Python312\site-packages\MySQLdb\connections.py", line 261, in query
    _mysql.connection.query(self, query)
MySQLdb.IntegrityError: (1364, "Field 'avg_coverage' doesn't have a default value")

The above exception was the direct cause of the following exception:

Traceback (most recent call last):
  File "C:\Users\kyawz\AppData\Roaming\Python\Python312\site-packages\django\core\handlers\exception.py", line 55, in inner
    response = get_response(request)
               ^^^^^^^^^^^^^^^^^^^^^
  File "C:\Users\kyawz\AppData\Roaming\Python\Python312\site-packages\django\core\handlers\base.py", line 197, in _get_response
    response = wrapped_callback(request, *callback_args, **callback_kwargs)
               ^^^^^^^^^^^^^^^^^^^^^^^^^^^^^^^^^^^^^^^^^^^^^^^^^^^^^^^^^^^^
  File "C:\Users\kyawz\AppData\Roaming\Python\Python312\site-packages\django\contrib\auth\decorators.py", line 23, in _wrapper_view
    return view_func(request, *args, **kwargs)
           ^^^^^^^^^^^^^^^^^^^^^^^^^^^^^^^^^^^
  File "C:\Users\kyawz\AppData\Roaming\Python\Python312\site-packages\django\utils\decorators.py", line 188, in _view_wrapper
    result = _process_exception(request, e)
             ^^^^^^^^^^^^^^^^^^^^^^^^^^^^^^
  File "C:\Users\kyawz\AppData\Roaming\Python\Python312\site-packages\django\utils\decorators.py", line 186, in _view_wrapper
    response = view_func(request, *args, **kwargs)
               ^^^^^^^^^^^^^^^^^^^^^^^^^^^^^^^^^^^
  File "C:\Users\kyawz\Desktop\filecompare_project\filecompare\views.py", line 40, in upload_files
    results = compare_files(file_paths, request.user.id, name_of_comparison)
              ^^^^^^^^^^^^^^^^^^^^^^^^^^^^^^^^^^^^^^^^^^^^^^^^^^^^^^^^^^^^^^
  File "C:\Users\kyawz\Desktop\filecompare_project\filecompare\utils.py", line 486, in compare_files
    comparison = Comparison.objects.create(
                 ^^^^^^^^^^^^^^^^^^^^^^^^^^
  File "C:\Users\kyawz\AppData\Roaming\Python\Python312\site-packages\django\db\models\manager.py", line 87, in manager_method
    return getattr(self.get_queryset(), name)(*args, **kwargs)
           ^^^^^^^^^^^^^^^^^^^^^^^^^^^^^^^^^^^^^^^^^^^^^^^^^^^
  File "C:\Users\kyawz\AppData\Roaming\Python\Python312\site-packages\django\db\models\query.py", line 679, in create
    obj.save(force_insert=True, using=self.db)
  File "C:\Users\kyawz\Desktop\filecompare_project\filecompare\models.py", line 130, in save
    super().save(*args, **kwargs)
  File "C:\Users\kyawz\AppData\Roaming\Python\Python312\site-packages\django\db\models\base.py", line 822, in save
    self.save_base(
  File "C:\Users\kyawz\AppData\Roaming\Python\Python312\site-packages\django\db\models\base.py", line 909, in save_base
    updated = self._save_table(
              ^^^^^^^^^^^^^^^^^
  File "C:\Users\kyawz\AppData\Roaming\Python\Python312\site-packages\django\db\models\base.py", line 1071, in _save_table
    results = self._do_insert(
              ^^^^^^^^^^^^^^^^
  File "C:\Users\kyawz\AppData\Roaming\Python\Python312\site-packages\django\db\models\base.py", line 1112, in _do_insert
    return manager._insert(
           ^^^^^^^^^^^^^^^^
  File "C:\Users\kyawz\AppData\Roaming\Python\Python312\site-packages\django\db\models\manager.py", line 87, in manager_method
    return getattr(self.get_queryset(), name)(*args, **kwargs)
           ^^^^^^^^^^^^^^^^^^^^^^^^^^^^^^^^^^^^^^^^^^^^^^^^^^^
  File "C:\Users\kyawz\AppData\Roaming\Python\Python312\site-packages\django\db\models\query.py", line 1847, in _insert
    return query.get_compiler(using=using).execute_sql(returning_fields)
           ^^^^^^^^^^^^^^^^^^^^^^^^^^^^^^^^^^^^^^^^^^^^^^^^^^^^^^^^^^^^^
  File "C:\Users\kyawz\AppData\Roaming\Python\Python312\site-packages\django\db\models\sql\compiler.py", line 1823, in execute_sql
    cursor.execute(sql, params)
  File "C:\Users\kyawz\AppData\Roaming\Python\Python312\site-packages\django\db\backends\utils.py", line 122, in execute
    return super().execute(sql, params)
           ^^^^^^^^^^^^^^^^^^^^^^^^^^^^
  File "C:\Users\kyawz\AppData\Roaming\Python\Python312\site-packages\django\db\backends\utils.py", line 79, in execute
    return self._execute_with_wrappers(
           ^^^^^^^^^^^^^^^^^^^^^^^^^^^^
  File "C:\Users\kyawz\AppData\Roaming\Python\Python312\site-packages\django\db\backends\utils.py", line 92, in _execute_with_wrappers
    return executor(sql, params, many, context)
           ^^^^^^^^^^^^^^^^^^^^^^^^^^^^^^^^^^^^
  File "C:\Users\kyawz\AppData\Roaming\Python\Python312\site-packages\django\db\backends\utils.py", line 100, in _execute
    with self.db.wrap_database_errors:
  File "C:\Users\kyawz\AppData\Roaming\Python\Python312\site-packages\django\db\utils.py", line 91, in __exit__
    raise dj_exc_value.with_traceback(traceback) from exc_value
  File "C:\Users\kyawz\AppData\Roaming\Python\Python312\site-packages\django\db\backends\utils.py", line 105, in _execute
    return self.cursor.execute(sql, params)
           ^^^^^^^^^^^^^^^^^^^^^^^^^^^^^^^^
  File "C:\Users\kyawz\AppData\Roaming\Python\Python312\site-packages\django\db\backends\mysql\base.py", line 76, in execute
    return self.cursor.execute(query, args)
           ^^^^^^^^^^^^^^^^^^^^^^^^^^^^^^^^
  File "C:\Users\kyawz\AppData\Roaming\Python\Python312\site-packages\MySQLdb\cursors.py", line 179, in execute
    res = self._query(mogrified_query)
          ^^^^^^^^^^^^^^^^^^^^^^^^^^^^
  File "C:\Users\kyawz\AppData\Roaming\Python\Python312\site-packages\MySQLdb\cursors.py", line 330, in _query
    db.query(q)
  File "C:\Users\kyawz\AppData\Roaming\Python\Python312\site-packages\MySQLdb\connections.py", line 261, in query
    _mysql.connection.query(self, query)
django.db.utils.IntegrityError: (1364, "Field 'avg_coverage' doesn't have a default value")
"POST /upload/ HTTP/1.1" 500 479513
